Workbook

Sheet Form responses 1
A1: Timestamp | B1: Email address | C1: Full Name (in Block Letters) | D1: Roll Number / Enrollment ID | E1: Course | F1: Contact Number | G1: Email | H1: Attending Convocation | I1: Hobbies & Personal Interests | J1: Sports & Games / Notable Achievements | K1: Hometown | L1: Passport Size Photo Upload | M1: Family Photo Upload | N1: Father's Name | O1: Father's Occupation / Designation & Affiliation | P1: Father's City / Place of Residence | Q1: Father's Contact Number | R1: Mother's Name | S1: Mother's Occupation / Designation & Affiliation | T1: Mother's City / Place of Residence | U1: Mother's Contact Number | V1: Number of Accompanying Guests | W1: Guest 1 Full Name | X1: Relation with the Student | Y1: Guest 2 Full Name | Z1: Relation with the Student 2 | AA1: Student Meal/Food Preference | AB1: Guest 1 Meal/Food Preference | AC1: Guest 2 Meal/Food Preference | AD1: Bus Drop Service Required on 15.09.2026 at 8:00 PM? | AE1: Number of Passengers for Bus Service
A2: 46258.758 | B2: aryalekshmi.micro_pgt23@aiimskalyani.edu.in | C2: Dr. ARYALEKSHMI. P | D2: 20230317 | E2: MD/MS/MDS 2023 | F2: 8547621028 | G2: draryalekshmi.p2020@gmail.com | H2: Yes | K2: Thiruvananthapuram | L2: https://drive.google.com/open?id=1Ve3rgelDyUKPtFnAdnGfSgKUXegGOroA | M2: https://drive.google.com/open?id=1hs75SNotCZp_qyhtSsg4KkQ1TyUXiwzD | N2: K.R. Praveen Kumar | O2: Business | P2: Thiruvananthapuram | Q2: 8078178289 | R2: S. Padmakumari Amma | S2: Business | T2: Thiruvananthapuram | U2: 9497639529 | V2: 2 | W2: Dr. Kannan. V. B | X2: Husband | Y2: Arjun. V. B | Z2: Brother | AA2: Non-Veg | AB2: Non-Veg | AC2: Non-Veg | AD2: Bus Drop Service not needed | AE2: 0
A3: 46258.788 | B3: tutul.9711@gmail.com | C3: ARUNDHATI MUKHERJEE | D3: 2023032 | E3: MD/MS/MDS 2023 | F3: 9051909471 | G3: tutul.9711@gmail.com | H3: Yes | I3: Drawing/Painting, Singing, Writing and Reading | J3: ACHIEVEMENTS - · PAPERS PRESENTED o Presented at Late Brig. Prof. G.S. Gopal Award for Best Post-Graduate Research Paper at SEOCON 2025. o Presented at the Resident Paper Award at NESCON 2025. o Presented at the Dr. Sandra Nisha D’Souza PG Award paper and the Dr. Anoop Raj and Dr. S.L. Chopra E-poster competitions at the 76th AOICON 2025 held at Kochi, Kerala. o Presented at Major KK Ghosh PGT paper presentation and E-poster presentation competitions at 52nd AOIWB 2025 held at Haldia, West Bengal. o Presented at Major KK Ghosh PGT paper presentation at 51st AOIWB, 2024 held at Kolkata. · AWARDS AND ACCOLADES o Participated at the 18th Dr. SM Sen and Dr. Tarun Palit Temporal Bone Dissection Competition by AOIWB, in March 2026 held at Kolkata. o Winner of RHINOAESTHETICON 2025, Quiz held at AIIMS Kalyani in November, 2025. o Winner of Late Brig. Prof. G.S. Gopal Award for Best Post-Graduate Research Paper at SEOCON 2025, held at Pune, Maharashtra. o Winner of SEOCON 2025 ENT quiz, held at Pune, Maharashtra. o Winner of NESCON 2025 Quiz competition. o 2nd runner up in Resident Paper Award at NESCON 2025. o Winner of the Prof SN Choudhury and Dr. P Chatterjee, 52nd AOIWB ENT quiz 2025 held at Haldia, West Bengal. o Participated at the Rhinology quiz and the Dr. Prem Kakkar ENT quiz held at the 76th AOICON 2025 held at Kochi, Kerala. o Participated at the 17th Dr. SM Sen and Dr. Tarun Palit Temporal Bone Dissection Competition by AOIWB, in April 2025 held at Kolkata. o Participated at the Prof SN Choudhury and Dr. P Chatterjee, 51st AOIWBCON ENT quiz 2024 at Kolkata, West Bengal . COMPETITIVE EXAMS: Achieved AML Rank 11 in INI-SS July, 2026 exams. Currently pursuing MCh Plastic Surgery and Reconstructive Surgery at AIIMS Raipur. · ACADEMIC ACHIEVEMENTS AND AWARDS o Honors in MBBS in the subjects of Biochemistry, Pathology, Pharmacology, Forensic Medicine and Technology, Otorhinolaryngology, Ophthalmology, Community and Family Medicine, General Medicine, General Surgery and Paediatric Medicine and Neonatology. o Obtained highest marks and gold medals in MBBS in the subjects of Forensic Medicine and Technology, Otorhinolaryngology, Ophthalmology, Community and Family Medicine, General Medicine, General Surgery and Paediatric Medicine and Neonatology. o University topper in Paediatric medicine and Neonatology in MBBS. o Scored 75% in post-graduate exit exam for MS Otorhinolaryngology from AIIMS Kalyani | K3: Kolkata | L3: https://drive.google.com/open?id=1_j5e_JX1--W1J-lrq1oLNLFeWOWMawCh | M3: https://drive.google.com/open?id=1uY7TeX8m5oAoS51y5th6r-EeTDoPFDvM | N3: SAUBHIK MUKHERJEE | O3: RETIRED | P3: KOLKATA, WEST BENGAL | Q3: 9830298198 | R3: BAISHAKHI MUKHERJEE | S3: HOMEMAKER | T3: KOLKATA, WEST BENGAL | U3: 9830108655 | V3: 2 | W3: SAUBHIK MUKHERJEE | X3: FATHER | Y3: BAISHAKHI MUKHERJEE | Z3: MOTHER | AA3: Non-Veg | AB3: Non-Veg | AC3: Non-Veg | AD3: Bus Drop Service not needed | AE3: 0
A4: 46258.79 | B4: shivani.mbbs-2020@aiimskalyani.edu.in | C4: SHIVANI KUMARI | D4: 202001142 | E4: MBBS 2020 | F4: 9199180555 | G4: shivani.mbbs-2020@aiimskalyani.edu.in | H4: Yes | I4: Listening to music | K4: Patna | L4: https://drive.google.com/open?id=1RfJBGbLf99R16v5n9J2VAwbNPAdqNGMh | M4: https://drive.google.com/open?id=1STTeHRjW4WNongEoGig9psCiKAfLb4Xu | N4: Santosh Kumar | O4: Business man | P4: Patna | Q4: 9934802080 | R4: Ruby Kumari | S4: Housemaker | T4: Patna | U4: 7857869034 | V4: 2 | W4: Santosh Kumar | X4: Father | Y4: Ruby kumari | Z4: Mother | AA4: Veg | AB4: Veg | AC4: Veg | AD4: Bus Drop Service not needed | AE4: 0
A5: 46258.791 | B5: aman2.mbbs-2020@aiimskalyani.edu.in | C5: AMAN KUMAR | D5: 20200161 | E5: MBBS 2020 | F5: 8637357310 | G5: aman2.mbbs-2020@aiimskalyani.edu.in | H5: Yes | I5: Making connections with people, making memes, organising events. | J5: Worked as Cultural Representative for 1 year. | K5: Samastipur | L5: https://drive.google.com/open?id=1suZL-X0BxCLmYfcwzUijOzMezxZEVbSW | M5: https://drive.google.com/open?id=1ReqtzHanLhryyFBG63TCBQgMGflMz5Pd | N5: Ajay Kumar Yadav | O5: Lawyer | P5: Samastipur, Bihar | Q5: 9852206837 | R5: Poonam Devi | S5: Homemaker | T5: Samastipur,Bihar | U5: 9431815713 | V5: 2 | W5: Ajay Kumar Yadav | X5: Father | Y5: Poonam Devi | Z5: Mother | AA5: Non-Veg | AB5: Non-Veg | AC5: Non-Veg | AD5: Drop at Kalyani Railway Station | AE5: 3
A6: 46258.793 | B6: tanishabiswas2412@gmail.com | C6: TANISHA BISWAS | D6: 20210256 | E6: B.Sc (Hons) Nursing 2021 | F6: 9735901944 | G6: tanishabiswas2412@gmail.com | H6: Yes | I6: I enjoy working out and staying active, with a particular interest in strength training and fitness. I also like cooking and art. | J6: I do like to play badminton (won badminton doubles in the college annual sports ) | K6: Krishnanagar, Nadia | L6: https://drive.google.com/open?id=1NCOOa_8VmPy1X5FhFx0U4oSo3SKqIgY8 | M6: https://drive.google.com/open?id=17i92BzKwyN2k5VhycQ5DI3h-7HMpDCX2 | N6: TAPAN KUMAR BISWAS | O6: Govt. Services ( Income Tax Office Superintendent ) | P6: Krishnanagar, Nadia | Q6: 9477330097 | R6: SUPRIYA BISWAS | S6: Home maker | T6: Krishnanagar | U6: 9775529810 | V6: 2 | W6: SUPRIYA BISWAS | X6: Mother | Y6: TAPAN KUMAR BISWAS | Z6: Father | AA6: Non-Veg | AB6: Non-Veg | AC6: Non-Veg | AD6: Bus Drop Service not needed | AE6: 0
A7: 46258.796 | B7: sandeepp.mbbs-2020@aiimskalyani.edu.in | C7: SANDEEP KUMAR PATRO | D7: 202001133 | E7: MBBS 2020 | F7: 7205409551 | G7: sandeepp.mbbs-2020@aiimskalyani.edu.in | H7: Yes | I7: Swimming | J7: Nothing | K7: Bhubaneswar | L7: https://drive.google.com/open?id=1eN9KhEi0TCm-OcRLJmS5rKVoLJwRf1mI | M7: https://drive.google.com/open?id=1Ri09OkjQVrb-B_-sNHrLb7K3aF2Lqv5V | N7: Rabindra Nath Patro | O7: Pharmacist | P7: Bhubaneswar | Q7: 9438602542 | R7: Sarita Patro | S7: Housewife | T7: Bhubaneswar | U7: 9692630419 | V7: 2 | W7: Rabindra Nath Patro | X7: Father | Y7: Sarita Patro | Z7: Mother | AA7: Non-Veg | AB7: Non-Veg | AC7: Non-Veg | AD7: Drop at Kalyani Railway Station | AE7: 3
A8: 46258.801 | B8: kaki.mbbs-2020@aiimskalyani.edu.in | C8: Kaki Jessica Pal | D8: 55/ 202001105 | E8: MBBS 2020 | F8: 8328165594 | G8: kaki.mbbs-2020@aiimskalyani.edu.in | H8: Yes | K8: Hyderabad, Telangana | L8: https://drive.google.com/open?id=1h4VpzyKvgyDNNcYVeW6ly6tOWqJOXtMs | M8: https://drive.google.com/open?id=1RcZNsQ-1elCc1ADBnjl4hCbodpnOgm9- | N8: Kaki V Jayapal Babu | O8: DGM, CSD department, ECIL, Hyderabad. | P8: Hyderabad | Q8: 9441666885 | R8: N Yesumanimma | S8: Senior Assistant, Smt. Durgabai Deshmukh Government Women's Technical Training Institute of technology and science, Hyderabad | T8: Hyderabad | U8: 9246348343 | V8: 2 | W8: Kaki V Jayapal Babu | X8: Father | Y8: N Yesumanimma | Z8: Mother | AA8: Non-Veg | AB8: Non-Veg | AC8: Non-Veg | AD8: Bus Drop Service not needed
A9: 46258.805 | B9: pritharoy426@gmail.com | C9: PRITHA ROY | D9: 20210238 | E9: B.Sc (Hons) Nursing 2021 | F9: 8777026833 | G9: pritha1405@gmail.com | H9: Yes | I9: Doodling,Crafting,Gardening,Digital Video Editing | J9: Scouts and Guide Certified and Crafting Certificate and Organisation Certificate | K9: Kolkata | L9: https://drive.google.com/open?id=1YRRwubDBrdrwOYwpaBVXTz6uwcv90LO- | M9: https://drive.google.com/open?id=1Tt51dZ7qtQV2avZFs44rQOLmeiBAiqLl | N9: Mr. Dipak Kumar Roy | O9: Retired Optometrist | P9: Kolkata | Q9: 9830349736 | R9: Mrs. Soma Roy | S9: Staff Nurse | T9: Kolkata | U9: 9051166452 | V9: 2 | W9: Mr. Dipak Kumar Roy | X9: Father | Y9: Mrs. Soma Roy | Z9: Mother | AA9: Non-Veg | AB9: Non-Veg | AC9: Non-Veg | AD9: Bus Drop Service not needed | AE9: 0
A10: 46258.874 | B10: anirudh.mbbs-2020@aiimskalyani.edu.in | C10: ANIRUDH GUPTA | D10: 17 / 20200167 | E10: MBBS 2020 | F10: 9464906137 | G10: anirudh.mbbs-2020@aiimskalyani.edu.in | H10: Yes | I10: I like travelling, aviation and watching sitcoms. | J10: - Joint organising secretary of "Elyssia" 1.0 - Editor-in-chief of "Samhita" 2.0 | K10: Chandigarh | L10: https://drive.google.com/open?id=1PSXf2zicyWI65fLmGUfogSav7KQ6IW7Y | M10: https://drive.google.com/open?id=1nSrmZabl9dLEuU_jVo6OP4hFGyxYvmcW | N10: Dr. Vivek Gupta | O10: Additional Director Interventional Neuroradiology Fortis Hospital Mohali Punjab | P10: Chandigarh | Q10: 7087009871 | R10: Dr. Madhu Gupta | S10: Professor Department of Community Medicine and School of Public Health PGIMER, Chandigarh | T10: Chandigarh | U10: 7087008223 | V10: 2 | W10: Dr. Vivek Gupta | X10: Father | Y10: Dr. Madhu Gupta | Z10: Mother | AA10: Non-Veg | AB10: Veg | AC10: Veg | AD10: Drop at Kolkata Airport | AE10: 3
A11: 46258.875 | B11: sandeep.mbbs-2020@aiimskalyani.edu.in | C11: SANDEEP KUMAR | D11: 202001132 | E11: MBBS 2020 | F11: 9142602801 | G11: sandeep.mbbs-2020@aiimskalyani.edu.in | H11: Yes | I11: Sports,Watching movies,Singing and many other. | J11: Gully cricket | K11: Jehanabad | L11: https://drive.google.com/open?id=1kqkAzE1eOmrtdmrzRw8esKmszv6pTXiS | M11: https://drive.google.com/open?id=1Bt6RqjcZymSOtepnin9GtCneOooOhk1b | N11: Shree Upendra prasad | O11: Farmer | P11: Jehanabad | Q11: 8427188157 | R11: Shreemati Neelam Kumari | S11: Auxiliary Nurse Midwife | T11: Jehanabad | U11: 9572285253 | V11: 2 | W11: Shree Upendra Prasad | X11: Father | Y11: Shreemati Neelam kumari | Z11: Mother | AA11: Non-Veg | AB11: Veg | AC11: Veg | AD11: Bus Drop Service not needed
A12: 46258.883 | B12: megha.bscnursing-2021@aiimskalyani.edu.in | C12: MEGHA MAITI | D12: 20210221 | E12: B.Sc (Hons) Nursing 2021 | F12: 9593286407 | G12: meghamaiti288@gmail.com | H12: Yes | I12: Drawing | J12: NA | K12: Dakshin Mechogram, Panskura, Purba Medinipur | L12: https://drive.google.com/open?id=1yx_mTJmpBlS7Ehjr2FkvxGn7j9Nj2wg3 | M12: https://drive.google.com/open?id=1r05u7kaR07v-0XzX50YXDcEiRVbJywIM | N12: NITAI CHARAN MAITI | O12: Retired Bank employee | P12: Dakshin Mechogram, Panskura, Purba Medinipur | Q12: 9434804867 | R12: LATE NABANITA MAITI | S12: NA | T12: NA | U12: 9434129205 | V12: 2 | W12: SUSAMA GHORAI | X12: Sister | Y12: SOURYA MAITI | Z12: Brother | AA12: Non-Veg | AB12: Non-Veg | AC12: Non-Veg | AD12: Bus Drop Service not needed | AE12: 0
A13: 46258.883 | B13: mukherjeeadrita8@gmail.com | C13: ADRITA MUKHERJEE | D13: 20210202 | E13: B.Sc (Hons) Nursing 2021 | F13: 9382419184 | G13: mukherjeeadrita8@gmail.com | H13: Yes | I13: Drawing | K13: Midnapore | L13: https://drive.google.com/open?id=1gZ6v76lU3CFE6kKfseufO2_k_gc7KcL8 | M13: https://drive.google.com/open?id=1DFJGA8riZ87Ou3GVZQWgBDMuQAqU9SFj | N13: ANIRBAN MUKHERJEE | O13: Senior Technician Incharge signal department Railway employee kgp junction | P13: Midnapore | Q13: 7595081828 | R13: MAHUA MUKHERJEE | S13: HOUSEWIFE | T13: MIDNAPORE | U13: 9434139015 | V13: 2 | W13: ANIRBAN MUKHERJEE | X13: Father | Y13: MAHUA MUKHERJEE | Z13: Mother | AA13: Non-Veg | AB13: Veg | AC13: Non-Veg | AD13: Bus Drop Service not needed | AE13: 0
A14: 46258.884 | B14: souvik.patho_pgt23@aiimskalyani.edu.in | C14: SOUVIK BHATTACHARYA | D14: 20230315 | E14: MD/MS/MDS 2023 | F14: 8017164337 | G14: svkbhttchr@live.in | H14: Yes | I14: Gardening | J14: NA | K14: Kolkata | L14: https://drive.google.com/open?id=1hExh2JwuT6TMN4Mg4IBFwmLaqAZa85G0 | M14: https://drive.google.com/open?id=1u_rmdsZQkqSLw89Wr3hh4895kQxU6rCH | N14: Saswata Bhattacharyya | O14: Doctor | P14: Kolkata | Q14: 9433879722 | R14: Sanghamitra Bhattacharya | S14: Teacher | T14: Kolkata | U14: 9433336318 | V14: 2 | W14: Saswata Bhattacharyya | X14: Father | Y14: Sanghamitra Bhattacharya | Z14: Mother | AA14: Non-Veg | AB14: Veg | AC14: Non-Veg | AD14: Drop at Kolkata Airport | AE14: 3
A15: 46258.889 | B15: soumya.mbbs-2020@aiimskalyani.edu.in | C15: SOUMYA PARIDA | D15: 202001148 | E15: MBBS 2020 | F15: 7735479962 | G15: paridasoumya1@gmail.com | H15: Yes | K15: Kendrapada , Odisha | L15: https://drive.google.com/open?id=1zTOBxVNCXt22Rwj7Pl1gpjJkQa8kWMSn | M15: https://drive.google.com/open?id=1UJUiJTyL0PYyi87H4TV5zhX-DzbNR0lw | N15: Pravat Kumar Parida | O15: Physics lecture | P15: Kendrapada, Odisha | Q15: 7008620644 | R15: Bandita Routray | S15: Teacher | T15: Kendrapada, Odisha | U15: 7008072294 | V15: 2 | W15: Shraddha saraswati Parida | X15: Sister | Y15: Pravat Kumar Parida | Z15: Father | AA15: Veg | AB15: Veg | AC15: Veg | AD15: Drop at Kolkata Airport | AE15: 3
A16: 46258.935 | B16: aditi.bscnursing-2021@aiimskalyani.edu.in | C16: ADITI MANDAL | D16: 20210201 | E16: B.Sc (Hons) Nursing 2021 | F16: 7584874474 | G16: aditimandal0328@gmail.com | H16: Yes | I16: Painting | K16: Purba Barddhaman, West Bengal | L16: https://drive.google.com/open?id=1jTIq7YFhMjFF20qzi_laHszNnwT09IJ5 | M16: https://drive.google.com/open?id=1jY1Pfr68oNoCTqmnwGvgYXorqJPrNTfD | N16: Sakti Pada Mandal | O16: Ex service man | P16: Purba Barddhaman | Q16: 7477517960 | R16: Shyamali Mandal | S16: Housewife | T16: Purba Barddhaman | U16: 9732142457 | V16: 2 | W16: Sakti Pada Mandal | X16: Father | Y16: Shyamali Mandal | Z16: Mother | AA16: Non-Veg | AB16: Non-Veg | AC16: Non-Veg | AD16: Bus Drop Service not needed | AE16: 0
A17: 46258.977 | B17: prasu1999cmc@gmail.com | C17: PRASANJIT DAS | D17: 20230320 | E17: MD/MS/MDS 2023 | F17: 9476084509 | G17: docprasanjitdas@gmail.com | H17: Yes | I17: Online educator, Researcher, Poet and Quiz master | J17: ICTD QUIZ COORDINATOR FOR AIIMS UG STUDENTS FOR TWO CONSECUTIVE YEARS, AUTHOR OF COLLECTION OF POEMS NAMED WINGS OF IMAGINATION PART 1,2 and 3, T-SHIRT BRAND OWNER, CREATOR | K17: PORT BLAIR | L17: https://drive.google.com/open?id=1SWuwHRxyno1L65hUqbVUCARa8kB9WwfS | M17: https://drive.google.com/open?id=1eN3XM3FDAfnjuzltq2F02E95vygNgK8o | N17: PRASANTA KUMAR DAS | O17: GOVERNMENT SERVANT ASSISTANT INCHARGE | P17: PORT BLAIR | Q17: 9434264702 | R17: TAPASI RANI DAS | S17: RETIRED GOVERNMENT SERVANT | T17: PORT BLAIR | U17: 9474231697 | V17: 2 | W17: PRASANTA KUMAR DAS | X17: FATHER | Y17: TAPASI RANI DAS | Z17: MOTHER | AA17: Non-Veg | AB17: Non-Veg | AC17: Non-Veg | AD17: Bus Drop Service not needed | AE17: 0
A18: 46259.029 | B18: chayanika.bscnursing-2021@aiimskalyani.edu.in | C18: CHAYANIKA BHATTACHARYYA | D18: 20210210 | E18: B.Sc (Hons) Nursing 2021 | F18: 9830079476 | G18: chayanikabhattacharyya4948@gmail.com | H18: Yes | I18: I am an avid listener of audio stories, enjoy expressing my thoughts through poetry, and love dancing occasionally. | J18: Nothing as such | K18: Sodepur | L18: https://drive.google.com/open?id=1LwqSTi2fSQe0ScwNC2r5BtXOsq_ISJ1o | M18: https://drive.google.com/open?id=1t8EZibcMxmHBFmMnZsEeQLKarEkZlhfi | N18: Biswajit Bhattacharyya | O18: Government service, Assistant Secretary, department of Public Health Engineering( PHE) , West Bengal government | P18: Sodepur | Q18: 9830035498 | R18: Aparna Bhattacharyya | S18: Government service, police in Department of Disaster Management and Civil Defence , West Bengal government | T18: Sodepur | U18: 7980652856 | V18: 2 | W18: Aparna bhattacharyya | X18: Mother | Y18: Kosturi singha roy | Z18: Aunt | AA18: Non-Veg | AB18: Non-Veg | AC18: Non-Veg | AD18: Drop at Kalyani Railway Station | AE18: 3
A19: 46259.385 | B19: shabnam.bscnursing-2021@aiimskalyani.edu.in | C19: SHABNAM PARVIN | D19: 20210248 | E19: B.Sc (Hons) Nursing 2021 | F19: 6297820802 | G19: parvinshabnam2002@gmail.com | H19: Yes | I19: Story reading | J19: No | K19: Bharatpur | L19: https://drive.google.com/open?id=1bo6OujeREw0L8EjGlISNIBR_OR-ZWkZg | M19: https://drive.google.com/open?id=1tb-MIGQ5GOylf6dZBWRVO2WA8GCWKCDi | N19: IDRISH ALI | O19: Retired headmaster | P19: Bharatpur | Q19: 9474314028 | R19: JESMINNHAR BEGUM | S19: NURSE | T19: Bharatpur | U19: 9564131918 | V19: 2 | W19: IDRISH ALI | X19: Father | Y19: JESMINNHAR BEGUM | Z19: Mother | AA19: Non-Veg | AB19: Non-Veg | AC19: Non-Veg | AD19: Bus Drop Service not needed | AE19: 0
A20: 46259.424 | B20: ghoshankita9732@gmail.com | C20: ANKITA GHOSH | D20: 20210205 | E20: B.Sc (Hons) Nursing 2021 | F20: 7550811864 | G20: ghoshankita9732@gmail.com | H20: Yes | I20: Drawing | J20: NA | K20: Howrah | L20: https://drive.google.com/open?id=12mVENRztApFqkfMj-N-EbI99DcOAnjQI | M20: https://drive.google.com/open?id=1sN-R1iU5tJvTKcjxNc8GxGMrBfPDcM1S | N20: Amit Ghosh | O20: Law clerk | P20: Howrah | Q20: 9732648905 | R20: Krishna Ghosh | S20: House wife | T20: Howrah | U20: 8509374801 | V20: 2 | W20: Amit Ghosh | X20: Father | Y20: Krishna Ghosh | Z20: Mother | AA20: Non-Veg | AB20: Non-Veg | AC20: Non-Veg | AD20: Bus Drop Service not needed | AE20: 0
A21: 46259.424 | B21: harukinanase1999@gmail.com | C21: Shreyasi Hati | D21: 20210260 | E21: B.Sc (Hons) Nursing 2021 | F21: 6297209181 | G21: harukinanase1999@gmail.com | H21: Yes | I21: Singing, Dancing, and writing stories. | J21: Sports- District level kabaddi and shot put player. Cultural - State level extempore and recitation winner, District level declamation winner 2024 in YPC. Various winning positions held in solo classical dance, drama, singing, literary hunt, quiz, debate, extempore, poem writing, slogan writing in inter house competitions during 4 years of college journey. Notable Achievements:- Traditionally published international novelist. Total books and anthology published - 6+. Books have been published in 133 countries including UK, USA, Canada, Japan, Australia and India through Ukiyoto Publishing India( An indian branch of Ukiyoto Japan) and featured in Amazon, Flipkart, Kobo Japan, Google books, Walmart etc. Awards & Honors:- Rising Star Award – 2020 Twisted Awards – 2020 Special Mention, Marine Awards (Short Story Category) – 2021 Women Icon Award – 2024 Golden Heritage Award – 2024 (Blue Star Publication) The Leading Attainers Award – “The Budding Author of the Year” – JEC Publications 7th Place, National Poetry Contest by S7 Rabindranath Tagore Hall of Fame Award – Welred Foundation International Recognition:- Invited Author, International Writers Assembly – Beijing, China (2025) Professional Affiliations:- Exclusive Author, A&D Entertainment Company (Webnovel Contract) | K21: Jamuria, Asansol | L21: https://drive.google.com/open?id=15VzPSTgmPpWXI6z2gRrbuOfp-S0xeTX8 | M21: https://drive.google.com/open?id=1kV_ewUUdJaWU4DsSMykLEI-oa4NRfwnQ | N21: Subrata Hati | O21: Gov. High School Teacher/ Assistant teacher in Birkulti N.G.M High School | P21: Jamuria, Asansol | Q21: 9474179653 | R21: Ivi Hati | S21: Home maker | T21: Jamuria, Asansol | U21: 7001010315 | V21: 2 | W21: Subrata Hati | X21: Father | Y21: Ivi Hati | Z21: Mother | AA21: Non-Veg | AB21: Non-Veg | AC21: Non-Veg | AD21: Bus Drop Service not needed | AE21: 0
A22: 46259.435 | B22: suchismitatikadar06@gmail.com | C22: SUCHISMITA TIKADAR | D22: 20210252 | E22: B.Sc (Hons) Nursing 2021 | F22: 8167823201 | G22: suchismitatikadar06@gmail.com | H22: Yes | I22: Listening to music | J22: CR in 4th year | K22: Barrackpore | L22: https://drive.google.com/open?id=1in8EqddpfEgt0T8H8C9u4-s47ybeLQym | M22: https://drive.google.com/open?id=1PfFNHgJaZ24VQtrXvxJkCNPtDZdprTPV | N22: Ramesh Chandra Tikadar | O22: Retired Railway Employee | P22: Barrackpore | Q22: 8101896944 | R22: Sima Tikadar | S22: House wife | T22: Barrackpore | U22: 7029022292 | V22: 2 | W22: Ramesh Chandra Tikadar | X22: Father | Y22: Sima Tikadar | Z22: Mother | AA22: Non-Veg | AB22: Non-Veg | AC22: Non-Veg | AD22: Drop at Kalyani Railway Station | AE22: 3
A23: 46259.437 | B23: amrit.mbbs-2020@aiimskalyani.edu.in | C23: AMRIT RAJ ANAND | D23: 20200163 | E23: MBBS 2020 | F23: 7484027360 | G23: amritrajanand51054@gmail.com | H23: Yes | I23: Football and Music | K23: Chhapra | L23: https://drive.google.com/open?id=1ebUTdcQyNy1kHGDWLP7si5Lr08i6dGfS | M23: https://drive.google.com/open?id=1_LznKduDz5f4pghoIv7j-MlwomF_NOaA | N23: CHANDAN SHARMA | O23: FARMER | P23: CHHAPRA | Q23: 8002729788 | R23: MANORMA SHARMA | S23: HOUSEWIFE | T23: CHHAPRA | U23: 8002729788 | V23: 2 | W23: RAM ANOOP SHRMA | X23: Grandfather | Y23: Nirmal Sharma | Z23: Uncle | AA23: Non-Veg | AB23: Veg | AC23: Veg | AD23: Bus Drop Service not needed | AE23: 0
A24: 46259.461 | B24: tuabanerjee1998@gmail.com | C24: SUKANYA BANERJEE | D24: 20210254 | E24: B.Sc (Hons) Nursing 2021 | F24: 8967823183 | G24: tuabanerjee1998@gmail.com | H24: Yes | I24: Reading books | K24: Basirhat | L24: https://drive.google.com/open?id=18VpKBK02odLSuP_Vz9lZWXzo-g8-Ho2p | M24: https://drive.google.com/open?id=15YmVzTzAigXyrk6ABa9nTOXGTUBg4ydd | N24: TAPAS BANERJEE | O24: Retired Government Employee | P24: Barasat | Q24: 9051225778 | R24: CHAITALI BANERJEE | S24: House Wife | T24: Barasat | U24: 9083248006 | V24: 2 | W24: Tapas Banerjee | X24: Father | Y24: Sreerup Banerjee | Z24: Brother | AA24: Non-Veg | AB24: Non-Veg | AC24: Non-Veg | AD24: Bus Drop Service not needed | AE24: 0
A25: 46259.468 | B25: awantika.mbbs-2020@aiimskalyani.edu.in | C25: AWANTIKA JHA | D25: Enrolment number: 20200181 | E25: MBBS 2020 | F25: 8918275082 | G25: awantika.mbbs-2020@aiimskalyani.edu.in | H25: Yes | I25: Poem writing, listening to music | K25: Durgapur | L25: https://drive.google.com/open?id=1swgdXG5ahfxdANZb31Jij9iuAiMrQ-GJ | M25: https://drive.google.com/open?id=1T6W7gCxCxiXRzLWClR30gfBGvOB7xvpI | N25: Vimalesh Kumar | O25: Deputy Accountant General/IAAS | P25: KOLKATA | Q25: 9434200996 | R25: Guriya Kumari | S25: Homemaker | T25: Durgapur | U25: 9339372714 | V25: 2 | W25: Vimalesh Kumar | X25: Father | Y25: Guriya Kumari | Z25: Mother | AA25: Veg | AB25: Veg | AC25: Veg | AD25: Bus Drop Service not needed | AE25: 0
A26: 46259.731 | B26: aritpriyo.mbbs-2020@aiimskalyani.edu.in | C26: ARITPRIYO GHOSH | D26: 24 | E26: MBBS 2020 | F26: 7339814841 | G26: rikghosh2015@gmail.com | H26: Yes | K26: Kalyani | L26: https://drive.google.com/open?id=1_lO5SQB-zGnpvwJKVcDPzkTOs5OgzmxX | M26: https://drive.google.com/open?id=1lM_Pqa4APkRd4ud8x3cCNVqZaH20aqcU | N26: Rajib Ghosh | O26: Government service | P26: Kalyani | Q26: 8017553865 | R26: Madhumita Ghosh | S26: Home maker | T26: Kalyani | U26: 6289116611 | V26: 2 | W26: Madhumita Ghosh | X26: Mother | Y26: Rajib Ghosh | Z26: Father | AA26: Non-Veg | AB26: Non-Veg | AC26: Non-Veg | AE26: 0
A27: 46259.739 | B27: samina.bscnursing-2021@aiimskalyani.edu.in | C27: SAMINA YASMIN | D27: 20210243 | E27: B.Sc (Hons) Nursing 2021 | F27: 8529460880 | G27: yasminsamina2312@gmail.com | H27: Yes | I27: Travelling and exploring new places Cooking and listening music | J27: NA | K27: Uttar Dinajpur | L27: https://drive.google.com/open?id=1ff7w9oWM0zZamED4L5zGFL1ShxRfELVm | M27: https://drive.google.com/open?id=15g0VUuS3eWOtYa4xYiE-49HMFJkGPJ_H | N27: MD.Islamuddin | O27: Servicemen ( Kolkata police) | P27: Uttar Dinajpur | Q27: 8777838566 | R27: Manwara Begam | S27: Housewife | T27: Uttar Dinajpur | U27: 9679153471 | V27: 1 | W27: MD . Islamuddin | X27: Father | Y27: NA | Z27: NA | AA27: Non-Veg | AB27: Non-Veg | AD27: Bus Drop Service not needed | AE27: 0
A28: 46259.76 | B28: mansi.singh2021@gmail.com | C28: DR MANSHI KUMARI | D28: 2023037 | E28: MD/MS/MDS 2023 | F28: 8207207670 | G28: mansi.singh2021@gmail.com | H28: Yes | K28: Varanasi,Uttar Pradesh | L28: https://drive.google.com/open?id=1l5jAcXwoQ-cvT-9G8LAGLweeEyCOYRNI | M28: https://drive.google.com/open?id=1SefSF4GXvJgrmCLfFNmLeUBeigtkZDqN | N28: Mr Raj Kumar Singh | O28: Civil Engineer | P28: Aurangabad ,Bihar | Q28: 9801120313 | R28: Geeta Singh | S28: Housewife | T28: Aurangabad,Bihar | U28: 9199013095 | V28: 2 | W28: Mr. Raj Kumar Singh | X28: Father | Y28: Dr Rishi Singh | Z28: Husband | AA28: Veg | AB28: Veg | AC28: Non-Veg | AD28: Bus Drop Service not needed | AE28: 0
A29: 46259.899 | B29: satyajit.mbbs-2020@aiimskalyani.edu.in | C29: SATYAJIT BEHERA | D29: 86(202001136) | E29: MBBS 2020 | F29: 8984155610 | G29: satyajit.mbbs-2020@aiimskalyani.edu.in | H29: Yes | I29: Studying | K29: Bhadrak | L29: https://drive.google.com/open?id=1pTCiAxTmh72cd1ew5dqtKt5o63zF4DVl | M29: https://drive.google.com/open?id=18yGlpiRX8BvHeQapF545hc1x-tS2uJog | N29: Ramakanta Behera | O29: Farmer | P29: Bhadrak | Q29: 8598018028 | R29: Minati Behera | S29: Housewife | T29: Bhadrak | U29: 8598018028 | V29: 2 | W29: Sasmita Barik | X29: Sister | Y29: Kashinath Barik | Z29: Brother | AA29: Non-Veg | AB29: Veg | AC29: Non-Veg | AD29: Bus Drop Service not needed | AE29: 0
A30: 46260.065 | B30: krishnas.mbbs-2020@aiimskalyani.edu.in | C30: KRISHNAS MAHI | D30: 58/202001108 | E30: MBBS 2020 | F30: 9110167850 | G30: krishnasmahi1@gmail.com | H30: Yes | I30: Cooking &Baking, makeup, painting | J30: No such | K30: Bhagalpur | L30: https://drive.google.com/open?id=1XTyHx4GbZQFlgWAkfnY_3DnqsZBqeupP | M30: https://drive.google.com/open?id=1P_X0YDbiCrcY9oVeF1sWkeovZYgKMExE | N30: Mr. Anupam Kumar Veena | O30: Businessman | P30: Bhagalpur | Q30: 7488610832 | R30: Mrs Pankhuri Verma | S30: Teacher | T30: Bhagalpur | U30: 9110904670 | V30: 2 | W30: Mr Anupam Kumar Verma | X30: Father | Y30: Mrs Pankhuri Verma | Z30: Mother | AA30: Non-Veg | AB30: Non-Veg | AC30: Non-Veg | AD30: Bus Drop Service not needed | AE30: 0
A31: 46260.109 | B31: riya.mbbs-2020@aiimskalyani.edu.in | C31: RIYA BEN | D31: 202001127 | E31: MBBS 2020 | F31: 8606774642 | G31: riya.mbbs-2020@aiimskalyani.edu.in | H31: Yes | I31: I play musical instruments like Keyboard and do Classical Dance. | J31: Achievements in Clinical case presentations and Quiz competitions. | K31: Palakkad,Kerala | L31: https://drive.google.com/open?id=1fxh5-Uv1aPb30bXsySbDnRVK9Y3Kg_gX | M31: https://drive.google.com/open?id=1b2PmDTvfM0tx4EnfWQ5zBGcJFZ-e_yhI | N31: BEN | O31: Doctor[Consultant Radiologist] & Owner[Ideal Diagnostics Centre] | P31: Madurai,Tamil Nadu | Q31: 9447277746 | R31: RANI BEN | S31: Administrator [Ideal Diagnostics Centre] | T31: Ernakulam,Kerala | U31: 9895637636 | V31: 2 | W31: BEN | X31: Father | Y31: RANI BEN | Z31: Mother | AA31: Non-Veg | AB31: Non-Veg | AC31: Non-Veg | AD31: Bus Drop Service not needed
A32: 46260.359 | B32: monalisa.biochem_pgt23@aiimskalyani.edu.in | C32: DR. MONALISA MAHAJAN | D32: 20230319 | E32: MD/MS/MDS 2023 | F32: 9531754461 | G32: monalisa.biochem_pgt23@aiimskalyani.edu.in | H32: Yes | I32: Art and craft | K32: Bankura | L32: https://drive.google.com/open?id=1Bjvem_I_ilRINZh5ay3Gh2MmbqyI_ZM5 | M32: https://drive.google.com/open?id=1w5oxEG3Y_3QnTCazzcYgvScpQnlHlUCB | N32: MADHAB KUMAR MAHAJAN | O32: BANK MANAGER (RETIRED) | P32: BANKURA | Q32: 9474185735 | R32: SOMA MAHAJAN | S32: HOME MAKER | T32: BANKURA | U32: 9475346936 | V32: 2 | W32: MADHAB KUMAR MAHAJAN | X32: FATHER | Y32: SOMA MAHAJAN | Z32: MOTHER | AA32: Non-Veg | AB32: Non-Veg | AC32: Non-Veg | AD32: Bus Drop Service not needed
A33: 46260.495 | B33: priyanka.bscnursing-2021@aiimskalyani.edu.in | C33: PRIYANKA | D33: 20210240 | E33: B.Sc (Hons) Nursing 2021 | F33: 9521473400 | G33: priyankasura11@gmail.com | H33: No
A34: 46260.558 | B34: subhodip.mbbs-2020@aiimskalyani.edu.in | C34: SUBHODIP DAS | D34: 101/202001151 | E34: MBBS 2020 | F34: 9679602964 | G34: subhodip.mbbs-2020@aiimskalyani.edu.in | H34: Yes | I34: Strong interest in football and video gaming. | J34: Football | K34: Asansol | L34: https://drive.google.com/open?id=1P6zVDGzkvgIb6Tdpk3ftQTaZgIxa5RHn | M34: https://drive.google.com/open?id=1pWB5DAklFhIBCDY88-lVSMw6USUqOUwf | N34: Uday Chand Das | O34: Retired Railway Personal | P34: Asansol | Q34: 7365841536 | R34: Archana Das | S34: Housewife | T34: Asansol | U34: 9832715653 | V34: 2 | W34: Uday Chand Das | X34: Father | Y34: Archana Das | Z34: Mother | AA34: Non-Veg | AB34: Non-Veg | AC34: Non-Veg | AD34: Bus Drop Service not needed | AE34: 0
A35: 46260.618 | B35: saravana.dentistry_pgt23@aiimskalyani.edu.in | C35: B.SARAVANA PRATHAP | D35: 20230313 | E35: MD/MS/MDS 2023 | F35: 9789409492 | G35: saravana.dentistry_pgt23@aiimskalyani.edu.in | H35: Yes | K35: Coimbatore | L35: https://drive.google.com/open?id=1thgAXDqCeAa3Di76_D8nIFLshDuiWyFK | M35: https://drive.google.com/open?id=1y7cM_212CUes9lf3DFTsE1oQt_gVIrf- | N35: C.Balachandran | O35: - | P35: - | Q35: 9566607472 | R35: B.Parvathi | S35: House wife | T35: Coimbatore | U35: 9566607472 | V35: 0 | AA35: Veg | AD35: Bus Drop Service not needed | AE35: 0
A36: 46260.675 | B36: megha.mbbs-2020@aiimskalyani.edu.in | C36: MEGHA HAZARIKA | D36: 202001112 | E36: MBBS 2020 | F36: 9518596484 | G36: meghahazarika270701@gmail.com | H36: Yes | I36: Dancing, Poetry | K36: Guwahati | L36: https://drive.google.com/open?id=1nBinud0RE0f_0prwiaAI5ZZNJcp5dUd7 | M36: https://drive.google.com/open?id=17NwuQxURpwnFXAM2DiR5BSKfqwrc4IpS | N36: Dr. Alokesh Hazarika | O36: Retired as CMO In-charge | P36: Dibrugarh | Q36: 9975994611 | R36: Shivani Hazarika | S36: Home maker | T36: Agra | U36: 9421192706 | V36: 2 | W36: Dr. Alokesh Hazarika | X36: Father | Y36: Diya | Z36: Cousin | AA36: Veg | AB36: Veg | AC36: Non-Veg | AD36: Bus Drop Service not needed | AE36: 0
A37: 46260.695 | B37: divyansh.mbbs-2020@aiimskalyani.edu.in | C37: DIVYANSH CHARAN | D37: 202001168 | E37: MBBS 2020 | F37: 8824714602 | G37: divyansh.mbbs-2020@aiimskalyani.edu.in | H37: Yes | I37: Singing | K37: Pali, Rajasthan | L37: https://drive.google.com/open?id=1I2vyciA0tArPcdiQVStjSbGUrAuBO1gl | M37: https://drive.google.com/open?id=18ktayzQ3enUk0YBzZUCarsxwHROZtm_i | N37: Mahesh Singh | O37: Police Inspector | P37: Jaipur | Q37: 9829045528 | R37: Kiran Charan | S37: Yoga Instructor | T37: Jaipur | U37: 9799096666 | V37: 2 | W37: Kiran Charan | X37: Mother | Y37: Mahesh Singh | Z37: Father | AA37: Veg | AB37: Veg | AC37: Veg | AD37: Bus Drop Service not needed | AE37: 0
A38: 46260.72 | B38: shraddha.mbbs-2020@aiimskalyani.edu.in | C38: SHRADDHA MATSYAPAL | D38: 93/202001143 | E38: MBBS 2020 | F38: 8319646271 | G38: shraddha.mbbs-2020@aiimskalyani.edu.in | H38: Yes | I38: Dancing, sketching and traveling | K38: Dhamtari | L38: https://drive.google.com/open?id=1IGN8QQZm9ZLtGrUOJzX5EeRq2LTFOeS9 | M38: https://drive.google.com/open?id=1sEgVY-mkTmcFAlq_VHH_zH8V7NRcRTZB | N38: Hemant Matsyapal | O38: Additional Collector | P38: Dhamtari | Q38: 9424220390 | R38: Ishwari Matsyapal | S38: Teacher | T38: Dhamtari | U38: 9406373960 | V38: 1 | W38: Ishwari Matsyapal | X38: Mother | AA38: Non-Veg | AB38: Non-Veg | AD38: Bus Drop Service not needed | AE38: 0
A39: 46260.721 | B39: ananya.mbbs-2020@aiimskalyani.edu.in | C39: ANANYA ARYANKITA | D39: 20200164 | E39: MBBS 2020 | F39: 9078841355 | G39: aryankita5@gmail.com | H39: Yes | I39: Reading novels, painting | J39: 1st position in 1st year MBBS professional exams. 3rd position in 4th year MBBS professional exams. | K39: Bhubaneswar | L39: https://drive.google.com/open?id=17b6bIqVkWSIkAmF68CQSxQ6jnC29-46V | M39: https://drive.google.com/open?id=15mg3M5L4ukDORUqgR1KRrFy6NNLA9FaA | N39: Krishna Prasad Samantaray | O39: Bank employee, Assistant General Manager | P39: Bhubaneswar | Q39: 9937014472 | R39: Jyotirmayee Nayak | S39: Homemaker | T39: Bhubaneswar | U39: 9937732588 | V39: 2 | W39: Krishna Prasad Samantaray | X39: Father | Y39: Jyotirmayee Nayak | Z39: Mother | AA39: Veg | AB39: Veg | AC39: Veg | AD39: Bus Drop Service not needed | AE39: 0
A40: 46260.835 | B40: paromitaghoshal10@gmail.com | C40: PAROMITA GHOSHAL | D40: 20210234 | E40: B.Sc (Hons) Nursing 2021 | F40: 6289704330 | G40: paromitaghoshal10@gmail.com | H40: Yes | I40: Listening music | J40: None | K40: Baruipur | L40: https://drive.google.com/open?id=1ndP96MZXOCBl_KkpL18Kdf8jW7Rmw5yY | M40: https://drive.google.com/open?id=1Nw6P4AOw8_4vSJ2OdAQZZ2qgMF3T045K | N40: Prabir Kumar Ghoshal | O40: Service | P40: Baruipur | Q40: 9836179253 | R40: Purnima Ghoshal | S40: Homemaker | T40: Baruipur | U40: 8013378159 | V40: 2 | W40: Prabir Kumar Ghoshal | X40: Father | Y40: Purnima Ghoshal | Z40: Mother | AA40: Non-Veg | AB40: Non-Veg | AC40: Non-Veg | AD40: Bus Drop Service not needed
...

Sheet Responses
A1: Timestamp | B1: Email address | C1: Full Name (in Block Letters) | D1: Roll Number / Enrollment ID | E1: Course | F1: Contact Number | G1: Email | H1: Attending Convocation | I1: Hobbies & Personal Interests | J1: Sports & Games / Notable Achievements | K1: Hometown | L1: Passport Size Photo Upload | M1: Family Photo Upload | N1: Father's Name | O1: Father's Occupation / Designation & Affiliation | P1: Father's City / Place of Residence | Q1: Father's Contact Number | R1: Mother's Name | S1: Mother's Occupation / Designation & Affiliation | T1: Mother's City / Place of Residence | U1: Mother's Contact Number | V1: Number of Accompanying Guests | W1: Guest 1 Full Name | X1: Relation with the Student | Y1: Guest 2 Full Name | Z1: Relation with the Student 2 | AA1: Student Meal/Food Preference | AB1: Guest 1 Meal/Food Preference | AC1: Guest 2 Meal/Food Preference | AD1: Bus Drop Service Required on 15.09.2026 at 8:00 PM? | AE1: Number of Passengers for Bus Service
A2: =IFERROR(__xludf.DUMMYFUNCTION("LET( raw, FILTER('Form responses 1'!A2:AE293, 'Form responses 1'!H2:H293=""Yes""), sorted, SORT(raw, 1, FALSE), c, CHOOSECOLS(sorted, 3), e, CHOOSECOLS(sorted, 5), k, ARRAYFORMULA(c & ""|"" & e), FILTER(sorted, MATCH(k, k, 0) = SEQUENCE(ROWS(k"&"))) )"),46270.99212284722) -> 46270.992 | B2: =IFERROR(__xludf.DUMMYFUNCTION("""COMPUTED_VALUE"""),"patel.mbbs-2020@aiimskalyani.edu.in") -> patel.mbbs-2020@aiimskalyani.edu.in | C2: =IFERROR(__xludf.DUMMYFUNCTION("""COMPUTED_VALUE"""),"PATEL SHRUTI RUTANJU ") -> PATEL SHRUTI RUTANJU | D2: =IFERROR(__xludf.DUMMYFUNCTION("""COMPUTED_VALUE"""),2.02001117E8) -> 202001117 | E2: =IFERROR(__xludf.DUMMYFUNCTION("""COMPUTED_VALUE"""),"MBBS 2020") -> MBBS 2020 | F2: =IFERROR(__xludf.DUMMYFUNCTION("""COMPUTED_VALUE"""),7.644977977E9) -> 7644977977 | G2: =IFERROR(__xludf.DUMMYFUNCTION("""COMPUTED_VALUE"""),"starv2888@gmail.com") -> starv2888@gmail.com | H2: =IFERROR(__xludf.DUMMYFUNCTION("""COMPUTED_VALUE"""),"Yes") -> Yes | I2: =IFERROR(__xludf.DUMMYFUNCTION("""COMPUTED_VALUE"""),"I love diving into board games and lively debates, goofing around with dogs, dabbling in performance arts and acting, and enjoying a little baking and swimming. I also love hands-on activities like LEGO, macramé, diamond art, and puzzles.") -> I love diving into board games and lively debates, goofing around with dogs, dabbling in performance arts and acting, and enjoying a little baking and swimming. I also love hands-on activities like LEGO, macramé, diamond art, and puzzles. | J2: =IFERROR(__xludf.DUMMYFUNCTION("""COMPUTED_VALUE"""),"Participated in debates Although I have never competed professionally, I thoroughly enjoy swimming.") -> Participated in debates Although I have never competed professionally, I thoroughly enjoy swimming. | K2: =IFERROR(__xludf.DUMMYFUNCTION("""COMPUTED_VALUE"""),"Scarborough, Maine & Anand, Gujarat") -> Scarborough, Maine & Anand, Gujarat | L2: =IFERROR(__xludf.DUMMYFUNCTION("""COMPUTED_VALUE"""),"https://drive.google.com/open?id=1wvVMWKrnUjVgP1CfYWdd_E0vchEM9pi3") -> https://drive.google.com/open?id=1wvVMWKrnUjVgP1CfYWdd_E0vchEM9pi3 | M2: =IFERROR(__xludf.DUMMYFUNCTION("""COMPUTED_VALUE"""),"https://drive.google.com/open?id=1FD55F3mUjSvviBFvT0lmlP5qs97Jo6Rq") -> https://drive.google.com/open?id=1FD55F3mUjSvviBFvT0lmlP5qs97Jo6Rq | N2: =IFERROR(__xludf.DUMMYFUNCTION("""COMPUTED_VALUE"""),"Late Rutanju Patel ") -> Late Rutanju Patel | O2: =IFERROR(__xludf.DUMMYFUNCTION("""COMPUTED_VALUE"""),"Certified Public Accountant (CPA) ;") -> Certified Public Accountant (CPA) ; | P2: =IFERROR(__xludf.DUMMYFUNCTION("""COMPUTED_VALUE"""),"N/A ") -> N/A | Q2: =IFERROR(__xludf.DUMMYFUNCTION("""COMPUTED_VALUE"""),9.999999999E9) -> 9999999999 | R2: =IFERROR(__xludf.DUMMYFUNCTION("""COMPUTED_VALUE"""),"Trupti Patel ") -> Trupti Patel | S2: =IFERROR(__xludf.DUMMYFUNCTION("""COMPUTED_VALUE"""),"Entrepreneur & Business Owner") -> Entrepreneur & Business Owner | T2: =IFERROR(__xludf.DUMMYFUNCTION("""COMPUTED_VALUE"""),"Scarborough, Maine & Anand, Gujarat ") -> Scarborough, Maine & Anand, Gujarat | U2: =IFERROR(__xludf.DUMMYFUNCTION("""COMPUTED_VALUE"""),9.429181978E9) -> 9429181978 | V2: =IFERROR(__xludf.DUMMYFUNCTION("""COMPUTED_VALUE"""),2.0) -> 2 | W2: =IFERROR(__xludf.DUMMYFUNCTION("""COMPUTED_VALUE"""),"Trupti Patel") -> Trupti Patel | X2: =IFERROR(__xludf.DUMMYFUNCTION("""COMPUTED_VALUE"""),"Mother ") -> Mother | Y2: =IFERROR(__xludf.DUMMYFUNCTION("""COMPUTED_VALUE"""),"Pranathi Nambiar ") -> Pranathi Nambiar | Z2: =IFERROR(__xludf.DUMMYFUNCTION("""COMPUTED_VALUE"""),"Cousin") -> Cousin | AA2: =IFERROR(__xludf.DUMMYFUNCTION("""COMPUTED_VALUE"""),"Veg") -> Veg | AB2: =IFERROR(__xludf.DUMMYFUNCTION("""COMPUTED_VALUE"""),"Veg") -> Veg | AC2: =IFERROR(__xludf.DUMMYFUNCTION("""COMPUTED_VALUE"""),"Non-Veg") -> Non-Veg | AD2: =IFERROR(__xludf.DUMMYFUNCTION("""COMPUTED_VALUE"""),"Drop at Kolkata Airport") -> Drop at Kolkata Airport | AE2: =IFERROR(__xludf.DUMMYFUNCTION("""COMPUTED_VALUE"""),2.0) -> 2
A3: =IFERROR(__xludf.DUMMYFUNCTION("""COMPUTED_VALUE"""),46269.758121631945) -> 46269.758 | B3: =IFERROR(__xludf.DUMMYFUNCTION("""COMPUTED_VALUE"""),"soni.bscnursing-2021@aiimskalyani.edu.in") -> soni.bscnursing-2021@aiimskalyani.edu.in | C3: =IFERROR(__xludf.DUMMYFUNCTION("""COMPUTED_VALUE"""),"SONI KUMARI ") -> SONI KUMARI | D3: =IFERROR(__xludf.DUMMYFUNCTION("""COMPUTED_VALUE"""),2.0210261E7) -> 20210261 | E3: =IFERROR(__xludf.DUMMYFUNCTION("""COMPUTED_VALUE"""),"B.Sc (Hons) Nursing 2021") -> B.Sc (Hons) Nursing 2021 | F3: =IFERROR(__xludf.DUMMYFUNCTION("""COMPUTED_VALUE"""),9.660339459E9) -> 9660339459 | G3: =IFERROR(__xludf.DUMMYFUNCTION("""COMPUTED_VALUE"""),"sahnisoni05@gmail.com") -> sahnisoni05@gmail.com | H3: =IFERROR(__xludf.DUMMYFUNCTION("""COMPUTED_VALUE"""),"Yes") -> Yes | I3: =IFERROR(__xludf.DUMMYFUNCTION("""COMPUTED_VALUE"""),"Playing various sports and exploring new places. ") -> Playing various sports and exploring new places. | J3: =IFERROR(__xludf.DUMMYFUNCTION("""COMPUTED_VALUE"""),"Represented the Bihar Table Tennis Association in competitive events, achieving multiple championship titles across district and inter-school tournaments. Additionally, secured 1st place in both the Singles and Doubles TT at the College Annual Sports Meet"&".") -> Represented the Bihar Table Tennis Association in competitive events, achieving multiple championship titles across district and inter-school tournaments. Additionally, secured 1st place in both the Singles and Doubles TT at the College Annual Sports Meet. | K3: =IFERROR(__xludf.DUMMYFUNCTION("""COMPUTED_VALUE"""),"Patna, Bihar ") -> Patna, Bihar | L3: =IFERROR(__xludf.DUMMYFUNCTION("""COMPUTED_VALUE"""),"https://drive.google.com/open?id=14Mpb3mx408Fe669jtBDA3eVsM3JQv8Ei") -> https://drive.google.com/open?id=14Mpb3mx408Fe669jtBDA3eVsM3JQv8Ei | M3: =IFERROR(__xludf.DUMMYFUNCTION("""COMPUTED_VALUE"""),"https://drive.google.com/open?id=1ZXw5JDk3nfR9UiFRHkn90J-K9uCKlxRP") -> https://drive.google.com/open?id=1ZXw5JDk3nfR9UiFRHkn90J-K9uCKlxRP | N3: =IFERROR(__xludf.DUMMYFUNCTION("""COMPUTED_VALUE"""),"Ramdeo Prasad") -> Ramdeo Prasad | O3: =IFERROR(__xludf.DUMMYFUNCTION("""COMPUTED_VALUE"""),"Businessman") -> Businessman | P3: =IFERROR(__xludf.DUMMYFUNCTION("""COMPUTED_VALUE"""),"Patna,Bihar") -> Patna,Bihar | Q3: =IFERROR(__xludf.DUMMYFUNCTION("""COMPUTED_VALUE"""),7.488140191E9) -> 7488140191 | R3: =IFERROR(__xludf.DUMMYFUNCTION("""COMPUTED_VALUE"""),"Mira Devi") -> Mira Devi | S3: =IFERROR(__xludf.DUMMYFUNCTION("""COMPUTED_VALUE"""),"Homemaker ") -> Homemaker | T3: =IFERROR(__xludf.DUMMYFUNCTION("""COMPUTED_VALUE"""),"Patna, Bihar") -> Patna, Bihar | U3: =IFERROR(__xludf.DUMMYFUNCTION("""COMPUTED_VALUE"""),7.439357998E9) -> 7439357998 | V3: =IFERROR(__xludf.DUMMYFUNCTION("""COMPUTED_VALUE"""),1.0) -> 1 | W3: =IFERROR(__xludf.DUMMYFUNCTION("""COMPUTED_VALUE"""),"ABHAY KUMAR") -> ABHAY KUMAR | X3: =IFERROR(__xludf.DUMMYFUNCTION("""COMPUTED_VALUE"""),"Brother") -> Brother | AA3: =IFERROR(__xludf.DUMMYFUNCTION("""COMPUTED_VALUE"""),"Non-Veg") -> Non-Veg | AB3: =IFERROR(__xludf.DUMMYFUNCTION("""COMPUTED_VALUE"""),"Non-Veg") -> Non-Veg | AD3: =IFERROR(__xludf.DUMMYFUNCTION("""COMPUTED_VALUE"""),"Bus Drop Service not needed") -> Bus Drop Service not needed
A4: =IFERROR(__xludf.DUMMYFUNCTION("""COMPUTED_VALUE"""),46269.63215892361) -> 46269.632 | B4: =IFERROR(__xludf.DUMMYFUNCTION("""COMPUTED_VALUE"""),"sonam.bscnursing-2021@aiimskalyani.edu.in") -> sonam.bscnursing-2021@aiimskalyani.edu.in | C4: =IFERROR(__xludf.DUMMYFUNCTION("""COMPUTED_VALUE"""),"SONAM KUMARI ") -> SONAM KUMARI | D4: =IFERROR(__xludf.DUMMYFUNCTION("""COMPUTED_VALUE"""),2.021025E7) -> 20210250 | E4: =IFERROR(__xludf.DUMMYFUNCTION("""COMPUTED_VALUE"""),"B.Sc (Hons) Nursing 2021") -> B.Sc (Hons) Nursing 2021 | F4: =IFERROR(__xludf.DUMMYFUNCTION("""COMPUTED_VALUE"""),8.404882688E9) -> 8404882688 | G4: =IFERROR(__xludf.DUMMYFUNCTION("""COMPUTED_VALUE"""),"sonamriva20@gmail.com") -> sonamriva20@gmail.com | H4: =IFERROR(__xludf.DUMMYFUNCTION("""COMPUTED_VALUE"""),"Yes") -> Yes | I4: =IFERROR(__xludf.DUMMYFUNCTION("""COMPUTED_VALUE"""),"Traveling and photography ") -> Traveling and photography | J4: =IFERROR(__xludf.DUMMYFUNCTION("""COMPUTED_VALUE"""),"Chess") -> Chess | K4: =IFERROR(__xludf.DUMMYFUNCTION("""COMPUTED_VALUE"""),"Bhagalpur ") -> Bhagalpur | L4: =IFERROR(__xludf.DUMMYFUNCTION("""COMPUTED_VALUE"""),"https://drive.google.com/open?id=1HVrHS_D5ahC18Hz1pfvs1DxJc9iE3i90") -> https://drive.google.com/open?id=1HVrHS_D5ahC18Hz1pfvs1DxJc9iE3i90 | M4: =IFERROR(__xludf.DUMMYFUNCTION("""COMPUTED_VALUE"""),"https://drive.google.com/open?id=1sVVHIaGT7Z-sRVXgXVs4t5l8lNrSP3Pe") -> https://drive.google.com/open?id=1sVVHIaGT7Z-sRVXgXVs4t5l8lNrSP3Pe | N4: =IFERROR(__xludf.DUMMYFUNCTION("""COMPUTED_VALUE"""),"Ranjan Kumar ") -> Ranjan Kumar | O4: =IFERROR(__xludf.DUMMYFUNCTION("""COMPUTED_VALUE"""),"Businessmen ") -> Businessmen | P4: =IFERROR(__xludf.DUMMYFUNCTION("""COMPUTED_VALUE"""),"Shahkund ") -> Shahkund | Q4: =IFERROR(__xludf.DUMMYFUNCTION("""COMPUTED_VALUE"""),8.404882688E9) -> 8404882688 | R4: =IFERROR(__xludf.DUMMYFUNCTION("""COMPUTED_VALUE"""),"Rani Devi ") -> Rani Devi | S4: =IFERROR(__xludf.DUMMYFUNCTION("""COMPUTED_VALUE"""),"Homemaker") -> Homemaker | T4: =IFERROR(__xludf.DUMMYFUNCTION("""COMPUTED_VALUE"""),"Shahkund") -> Shahkund | U4: =IFERROR(__xludf.DUMMYFUNCTION("""COMPUTED_VALUE"""),7.488505863E9) -> 7488505863 | V4: =IFERROR(__xludf.DUMMYFUNCTION("""COMPUTED_VALUE"""),2.0) -> 2 | W4: =IFERROR(__xludf.DUMMYFUNCTION("""COMPUTED_VALUE"""),"Ranjan Kumar ") -> Ranjan Kumar | X4: =IFERROR(__xludf.DUMMYFUNCTION("""COMPUTED_VALUE"""),"Father") -> Father | Y4: =IFERROR(__xludf.DUMMYFUNCTION("""COMPUTED_VALUE"""),"Rani Devi ") -> Rani Devi | Z4: =IFERROR(__xludf.DUMMYFUNCTION("""COMPUTED_VALUE"""),"Mother") -> Mother | AA4: =IFERROR(__xludf.DUMMYFUNCTION("""COMPUTED_VALUE"""),"Non-Veg") -> Non-Veg | AB4: =IFERROR(__xludf.DUMMYFUNCTION("""COMPUTED_VALUE"""),"Non-Veg") -> Non-Veg | AC4: =IFERROR(__xludf.DUMMYFUNCTION("""COMPUTED_VALUE"""),"Veg") -> Veg | AD4: =IFERROR(__xludf.DUMMYFUNCTION("""COMPUTED_VALUE"""),"Bus Drop Service not needed") -> Bus Drop Service not needed | AE4: =IFERROR(__xludf.DUMMYFUNCTION("""COMPUTED_VALUE"""),0.0) -> 0
A5: =IFERROR(__xludf.DUMMYFUNCTION("""COMPUTED_VALUE"""),46268.72020755787) -> 46268.72 | B5: =IFERROR(__xludf.DUMMYFUNCTION("""COMPUTED_VALUE"""),"agnibha.bscnursing-2021@aiimskalyani.edu.in") -> agnibha.bscnursing-2021@aiimskalyani.edu.in | C5: =IFERROR(__xludf.DUMMYFUNCTION("""COMPUTED_VALUE"""),"AGNIBHA PAUL ") -> AGNIBHA PAUL | D5: =IFERROR(__xludf.DUMMYFUNCTION("""COMPUTED_VALUE"""),2.0210203E7) -> 20210203 | E5: =IFERROR(__xludf.DUMMYFUNCTION("""COMPUTED_VALUE"""),"B.Sc (Hons) Nursing 2021") -> B.Sc (Hons) Nursing 2021 | F5: =IFERROR(__xludf.DUMMYFUNCTION("""COMPUTED_VALUE"""),6.296247051E9) -> 6296247051 | G5: =IFERROR(__xludf.DUMMYFUNCTION("""COMPUTED_VALUE"""),"agnibha.bscnursing-2021@aiimskalyani.edu.in") -> agnibha.bscnursing-2021@aiimskalyani.edu.in | H5: =IFERROR(__xludf.DUMMYFUNCTION("""COMPUTED_VALUE"""),"Yes") -> Yes | I5: =IFERROR(__xludf.DUMMYFUNCTION("""COMPUTED_VALUE"""),"Sketching , watching movies ") -> Sketching , watching movies | K5: =IFERROR(__xludf.DUMMYFUNCTION("""COMPUTED_VALUE"""),"Coochbehar, West Bengal ") -> Coochbehar, West Bengal | L5: =IFERROR(__xludf.DUMMYFUNCTION("""COMPUTED_VALUE"""),"https://drive.google.com/open?id=14ns53xW0g5r7rsAieCJaIPrfcLHXNG38") -> https://drive.google.com/open?id=14ns53xW0g5r7rsAieCJaIPrfcLHXNG38 | M5: =IFERROR(__xludf.DUMMYFUNCTION("""COMPUTED_VALUE"""),"https://drive.google.com/open?id=1gI65Z8yykq8K_GRtHkP7n8FulaboQPE-") -> https://drive.google.com/open?id=1gI65Z8yykq8K_GRtHkP7n8FulaboQPE- | N5: =IFERROR(__xludf.DUMMYFUNCTION("""COMPUTED_VALUE"""),"Shyamal Chandra Paul") -> Shyamal Chandra Paul | O5: =IFERROR(__xludf.DUMMYFUNCTION("""COMPUTED_VALUE"""),"Teacher ") -> Teacher | P5: =IFERROR(__xludf.DUMMYFUNCTION("""COMPUTED_VALUE"""),"Coochbehar,West Bengal ") -> Coochbehar,West Bengal | Q5: =IFERROR(__xludf.DUMMYFUNCTION("""COMPUTED_VALUE"""),6.29467189E9) -> 6294671890 | R5: =IFERROR(__xludf.DUMMYFUNCTION("""COMPUTED_VALUE"""),"Jwelli Basu Paul") -> Jwelli Basu Paul | S5: =IFERROR(__xludf.DUMMYFUNCTION("""COMPUTED_VALUE"""),"Health worker") -> Health worker | T5: =IFERROR(__xludf.DUMMYFUNCTION("""COMPUTED_VALUE"""),"Coochbehar, West Bengal ") -> Coochbehar, West Bengal | U5: =IFERROR(__xludf.DUMMYFUNCTION("""COMPUTED_VALUE"""),7.363871933E9) -> 7363871933 | V5: =IFERROR(__xludf.DUMMYFUNCTION("""COMPUTED_VALUE"""),2.0) -> 2 | W5: =IFERROR(__xludf.DUMMYFUNCTION("""COMPUTED_VALUE"""),"1. Shyamal Chandra Paul ") -> 1. Shyamal Chandra Paul | X5: =IFERROR(__xludf.DUMMYFUNCTION("""COMPUTED_VALUE"""),"Father") -> Father | Y5: =IFERROR(__xludf.DUMMYFUNCTION("""COMPUTED_VALUE"""),"Jwelli Basu Paul ") -> Jwelli Basu Paul | Z5: =IFERROR(__xludf.DUMMYFUNCTION("""COMPUTED_VALUE"""),"Mother") -> Mother | AA5: =IFERROR(__xludf.DUMMYFUNCTION("""COMPUTED_VALUE"""),"Veg") -> Veg | AB5: =IFERROR(__xludf.DUMMYFUNCTION("""COMPUTED_VALUE"""),"Non-Veg") -> Non-Veg | AC5: =IFERROR(__xludf.DUMMYFUNCTION("""COMPUTED_VALUE"""),"Non-Veg") -> Non-Veg | AD5: =IFERROR(__xludf.DUMMYFUNCTION("""COMPUTED_VALUE"""),"Bus Drop Service not needed") -> Bus Drop Service not needed | AE5: =IFERROR(__xludf.DUMMYFUNCTION("""COMPUTED_VALUE"""),0.0) -> 0
A6: =IFERROR(__xludf.DUMMYFUNCTION("""COMPUTED_VALUE"""),46266.996902349536) -> 46266.997 | B6: =IFERROR(__xludf.DUMMYFUNCTION("""COMPUTED_VALUE"""),"sharmistha.mbbs-2020@aiimskalyani.edu.in") -> sharmistha.mbbs-2020@aiimskalyani.edu.in | C6: =IFERROR(__xludf.DUMMYFUNCTION("""COMPUTED_VALUE"""),"SHARMISTHA ROUT") -> SHARMISTHA ROUT | D6: =IFERROR(__xludf.DUMMYFUNCTION("""COMPUTED_VALUE"""),2.02001139E8) -> 202001139 | E6: =IFERROR(__xludf.DUMMYFUNCTION("""COMPUTED_VALUE"""),"MBBS 2020") -> MBBS 2020 | F6: =IFERROR(__xludf.DUMMYFUNCTION("""COMPUTED_VALUE"""),8.905157891E9) -> 8905157891 | G6: =IFERROR(__xludf.DUMMYFUNCTION("""COMPUTED_VALUE"""),"sharmistha.mbbs-2020@aiimskalyani.edu.in") -> sharmistha.mbbs-2020@aiimskalyani.edu.in | H6: =IFERROR(__xludf.DUMMYFUNCTION("""COMPUTED_VALUE"""),"Yes") -> Yes | I6: =IFERROR(__xludf.DUMMYFUNCTION("""COMPUTED_VALUE"""),"My hobbies include painting , public speaking and academic quizzing .") -> My hobbies include painting , public speaking and academic quizzing . | K6: =IFERROR(__xludf.DUMMYFUNCTION("""COMPUTED_VALUE"""),"Bhubaneswar ") -> Bhubaneswar | L6: =IFERROR(__xludf.DUMMYFUNCTION("""COMPUTED_VALUE"""),"https://drive.google.com/open?id=1nVM8n8zHwMihrktdkrp1SMFAISMWQPh3") -> https://drive.google.com/open?id=1nVM8n8zHwMihrktdkrp1SMFAISMWQPh3 | M6: =IFERROR(__xludf.DUMMYFUNCTION("""COMPUTED_VALUE"""),"https://drive.google.com/open?id=16kxxoRKzyYMnXX9WcQjINwavwF-UhTEN") -> https://drive.google.com/open?id=16kxxoRKzyYMnXX9WcQjINwavwF-UhTEN | N6: =IFERROR(__xludf.DUMMYFUNCTION("""COMPUTED_VALUE"""),"Surendra Kumar Rout") -> Surendra Kumar Rout | O6: =IFERROR(__xludf.DUMMYFUNCTION("""COMPUTED_VALUE"""),"Retired general manager at NTPC, Kaniha") -> Retired general manager at NTPC, Kaniha | P6: =IFERROR(__xludf.DUMMYFUNCTION("""COMPUTED_VALUE"""),"Bhubaneswar ") -> Bhubaneswar | Q6: =IFERROR(__xludf.DUMMYFUNCTION("""COMPUTED_VALUE"""),8.905157891E9) -> 8905157891 | R6: =IFERROR(__xludf.DUMMYFUNCTION("""COMPUTED_VALUE"""),"Dr.Krishna Patro") -> Dr.Krishna Patro | S6: =IFERROR(__xludf.DUMMYFUNCTION("""COMPUTED_VALUE"""),"Associate professor at Department of Ophthalmology, PGIMER Bhubaneswar ") -> Associate professor at Department of Ophthalmology, PGIMER Bhubaneswar | T6: =IFERROR(__xludf.DUMMYFUNCTION("""COMPUTED_VALUE"""),"Bhubaneswar ") -> Bhubaneswar | U6: =IFERROR(__xludf.DUMMYFUNCTION("""COMPUTED_VALUE"""),8.905157891E9) -> 8905157891 | V6: =IFERROR(__xludf.DUMMYFUNCTION("""COMPUTED_VALUE"""),2.0) -> 2 | W6: =IFERROR(__xludf.DUMMYFUNCTION("""COMPUTED_VALUE"""),"Surendra Kumar Rout") -> Surendra Kumar Rout | X6: =IFERROR(__xludf.DUMMYFUNCTION("""COMPUTED_VALUE"""),"Father") -> Father | Y6: =IFERROR(__xludf.DUMMYFUNCTION("""COMPUTED_VALUE"""),"Dr.Krishna Patro") -> Dr.Krishna Patro | Z6: =IFERROR(__xludf.DUMMYFUNCTION("""COMPUTED_VALUE"""),"Mother") -> Mother | AA6: =IFERROR(__xludf.DUMMYFUNCTION("""COMPUTED_VALUE"""),"Non-Veg") -> Non-Veg | AB6: =IFERROR(__xludf.DUMMYFUNCTION("""COMPUTED_VALUE"""),"Non-Veg") -> Non-Veg | AC6: =IFERROR(__xludf.DUMMYFUNCTION("""COMPUTED_VALUE"""),"Non-Veg") -> Non-Veg | AD6: =IFERROR(__xludf.DUMMYFUNCTION("""COMPUTED_VALUE"""),"Bus Drop Service not needed") -> Bus Drop Service not needed | AE6: =IFERROR(__xludf.DUMMYFUNCTION("""COMPUTED_VALUE"""),0.0) -> 0
A7: =IFERROR(__xludf.DUMMYFUNCTION("""COMPUTED_VALUE"""),46266.935814675926) -> 46266.936 | B7: =IFERROR(__xludf.DUMMYFUNCTION("""COMPUTED_VALUE"""),"chongtham.mbbs-2020@aiimskalyani.edu.in") -> chongtham.mbbs-2020@aiimskalyani.edu.in | C7: =IFERROR(__xludf.DUMMYFUNCTION("""COMPUTED_VALUE"""),"CHONGTHAM PARITIYA SINGH") -> CHONGTHAM PARITIYA SINGH | D7: =IFERROR(__xludf.DUMMYFUNCTION("""COMPUTED_VALUE"""),2.0200188E7) -> 20200188 | E7: =IFERROR(__xludf.DUMMYFUNCTION("""COMPUTED_VALUE"""),"MBBS 2020") -> MBBS 2020 | F7: =IFERROR(__xludf.DUMMYFUNCTION("""COMPUTED_VALUE"""),7.011342677E9) -> 7011342677 | G7: =IFERROR(__xludf.DUMMYFUNCTION("""COMPUTED_VALUE"""),"chongtham.mbbs-2020@aiimskalyani.edu.in") -> chongtham.mbbs-2020@aiimskalyani.edu.in | H7: =IFERROR(__xludf.DUMMYFUNCTION("""COMPUTED_VALUE"""),"Yes") -> Yes | I7: =IFERROR(__xludf.DUMMYFUNCTION("""COMPUTED_VALUE"""),"Reading books, Watching anime") -> Reading books, Watching anime | J7: =IFERROR(__xludf.DUMMYFUNCTION("""COMPUTED_VALUE"""),"Participated in and hosted multiple Quiz events") -> Participated in and hosted multiple Quiz events | K7: =IFERROR(__xludf.DUMMYFUNCTION("""COMPUTED_VALUE"""),"Imphal, Manipur") -> Imphal, Manipur | L7: =IFERROR(__xludf.DUMMYFUNCTION("""COMPUTED_VALUE"""),"https://drive.google.com/open?id=1N44T7YnTBgmkiTbItQKtEUNpjEDd0EUh") -> https://drive.google.com/open?id=1N44T7YnTBgmkiTbItQKtEUNpjEDd0EUh | M7: =IFERROR(__xludf.DUMMYFUNCTION("""COMPUTED_VALUE"""),"https://drive.google.com/open?id=17f6tVYwvx4UzQXlhJ9Z6B_eDtJe69uqQ") -> https://drive.google.com/open?id=17f6tVYwvx4UzQXlhJ9Z6B_eDtJe69uqQ | N7: =IFERROR(__xludf.DUMMYFUNCTION("""COMPUTED_VALUE"""),"Chongtham Pureihanba Singh ") -> Chongtham Pureihanba Singh | O7: =IFERROR(__xludf.DUMMYFUNCTION("""COMPUTED_VALUE"""),"Assistant Director, FSL Delhi") -> Assistant Director, FSL Delhi | P7: =IFERROR(__xludf.DUMMYFUNCTION("""COMPUTED_VALUE"""),"Rohini, Delhi") -> Rohini, Delhi | Q7: =IFERROR(__xludf.DUMMYFUNCTION("""COMPUTED_VALUE"""),9.717515666E9) -> 9717515666 | R7: =IFERROR(__xludf.DUMMYFUNCTION("""COMPUTED_VALUE"""),"Chongtham Lenjibala Devi") -> Chongtham Lenjibala Devi | S7: =IFERROR(__xludf.DUMMYFUNCTION("""COMPUTED_VALUE"""),"Homemaker") -> Homemaker | T7: =IFERROR(__xludf.DUMMYFUNCTION("""COMPUTED_VALUE"""),"Rohini, Delhi") -> Rohini, Delhi | U7: =IFERROR(__xludf.DUMMYFUNCTION("""COMPUTED_VALUE"""),9.968443102E9) -> 9968443102 | V7: =IFERROR(__xludf.DUMMYFUNCTION("""COMPUTED_VALUE"""),2.0) -> 2 | W7: =IFERROR(__xludf.DUMMYFUNCTION("""COMPUTED_VALUE"""),"Chongtham Pureihanba Singh ") -> Chongtham Pureihanba Singh | X7: =IFERROR(__xludf.DUMMYFUNCTION("""COMPUTED_VALUE"""),"Father") -> Father | Y7: =IFERROR(__xludf.DUMMYFUNCTION("""COMPUTED_VALUE"""),"Sreeja Sarkar") -> Sreeja Sarkar | Z7: =IFERROR(__xludf.DUMMYFUNCTION("""COMPUTED_VALUE"""),"Cousin") -> Cousin | AA7: =IFERROR(__xludf.DUMMYFUNCTION("""COMPUTED_VALUE"""),"Non-Veg") -> Non-Veg | AB7: =IFERROR(__xludf.DUMMYFUNCTION("""COMPUTED_VALUE"""),"Non-Veg") -> Non-Veg | AC7: =IFERROR(__xludf.DUMMYFUNCTION("""COMPUTED_VALUE"""),"Non-Veg") -> Non-Veg | AD7: =IFERROR(__xludf.DUMMYFUNCTION("""COMPUTED_VALUE"""),"Bus Drop Service not needed") -> Bus Drop Service not needed | AE7: =IFERROR(__xludf.DUMMYFUNCTION("""COMPUTED_VALUE"""),0.0) -> 0
A8: =IFERROR(__xludf.DUMMYFUNCTION("""COMPUTED_VALUE"""),46266.86402688657) -> 46266.864 | B8: =IFERROR(__xludf.DUMMYFUNCTION("""COMPUTED_VALUE"""),"sanandaavidipta@gmail.com") -> sanandaavidipta@gmail.com | C8: =IFERROR(__xludf.DUMMYFUNCTION("""COMPUTED_VALUE"""),"SANANDA DAS") -> SANANDA DAS | D8: =IFERROR(__xludf.DUMMYFUNCTION("""COMPUTED_VALUE"""),2.0210244E7) -> 20210244 | E8: =IFERROR(__xludf.DUMMYFUNCTION("""COMPUTED_VALUE"""),"B.Sc (Hons) Nursing 2021") -> B.Sc (Hons) Nursing 2021 | F8: =IFERROR(__xludf.DUMMYFUNCTION("""COMPUTED_VALUE"""),9.330715505E9) -> 9330715505 | G8: =IFERROR(__xludf.DUMMYFUNCTION("""COMPUTED_VALUE"""),"sanandaavidipta@gmail.com") -> sanandaavidipta@gmail.com | H8: =IFERROR(__xludf.DUMMYFUNCTION("""COMPUTED_VALUE"""),"Yes") -> Yes | I8: =IFERROR(__xludf.DUMMYFUNCTION("""COMPUTED_VALUE"""),"Listening music ") -> Listening music | K8: =IFERROR(__xludf.DUMMYFUNCTION("""COMPUTED_VALUE"""),"TARAKESWAR ") -> TARAKESWAR | L8: =IFERROR(__xludf.DUMMYFUNCTION("""COMPUTED_VALUE"""),"https://drive.google.com/open?id=1q7vxH_QYaEU34MHppSGzd3NaWZVy8P2T") -> https://drive.google.com/open?id=1q7vxH_QYaEU34MHppSGzd3NaWZVy8P2T | M8: =IFERROR(__xludf.DUMMYFUNCTION("""COMPUTED_VALUE"""),"https://drive.google.com/open?id=1X-UOXjb8Wn9jTSc3KAMcoMLGo_4sEAiO") -> https://drive.google.com/open?id=1X-UOXjb8Wn9jTSc3KAMcoMLGo_4sEAiO | N8: =IFERROR(__xludf.DUMMYFUNCTION("""COMPUTED_VALUE"""),"Sushanta Das ") -> Sushanta Das | O8: =IFERROR(__xludf.DUMMYFUNCTION("""COMPUTED_VALUE"""),"Retired Army person ") -> Retired Army person | P8: =IFERROR(__xludf.DUMMYFUNCTION("""COMPUTED_VALUE"""),"TARAKESWAR ") -> TARAKESWAR | Q8: =IFERROR(__xludf.DUMMYFUNCTION("""COMPUTED_VALUE"""),6.284416397E9) -> 6284416397 | R8: =IFERROR(__xludf.DUMMYFUNCTION("""COMPUTED_VALUE"""),"Piyali Das") -> Piyali Das | S8: =IFERROR(__xludf.DUMMYFUNCTION("""COMPUTED_VALUE"""),"House wife ") -> House wife | T8: =IFERROR(__xludf.DUMMYFUNCTION("""COMPUTED_VALUE"""),"TARAKESWAR ") -> TARAKESWAR | U8: =IFERROR(__xludf.DUMMYFUNCTION("""COMPUTED_VALUE"""),8.910037049E9) -> 8910037049 | V8: =IFERROR(__xludf.DUMMYFUNCTION("""COMPUTED_VALUE"""),2.0) -> 2 | W8: =IFERROR(__xludf.DUMMYFUNCTION("""COMPUTED_VALUE"""),"Sushanta Das ") -> Sushanta Das | X8: =IFERROR(__xludf.DUMMYFUNCTION("""COMPUTED_VALUE"""),"Father ") -> Father | Y8: =IFERROR(__xludf.DUMMYFUNCTION("""COMPUTED_VALUE"""),"Piyali Das ") -> Piyali Das | Z8: =IFERROR(__xludf.DUMMYFUNCTION("""COMPUTED_VALUE"""),"Mother ") -> Mother | AA8: =IFERROR(__xludf.DUMMYFUNCTION("""COMPUTED_VALUE"""),"Non-Veg") -> Non-Veg | AB8: =IFERROR(__xludf.DUMMYFUNCTION("""COMPUTED_VALUE"""),"Non-Veg") -> Non-Veg | AC8: =IFERROR(__xludf.DUMMYFUNCTION("""COMPUTED_VALUE"""),"Non-Veg") -> Non-Veg | AD8: =IFERROR(__xludf.DUMMYFUNCTION("""COMPUTED_VALUE"""),"Drop at Kalyani Railway Station") -> Drop at Kalyani Railway Station | AE8: =IFERROR(__xludf.DUMMYFUNCTION("""COMPUTED_VALUE"""),3.0) -> 3
